Workbook
Name lst_Books: 'My Books'!$B$5:$B$24
Name lst_BookTypes: Config!$E$5:$E$15
Name lst_Series: 'Universes & Series'!$A$5:$A$24
Name lst_Stages: Config!$F$5:$F$14
Name lst_Universes: Config!$G$5:$G$15

Sheet Dashboard
A1: 🌟 AUTHOR ECOSYSTEM • EXECUTIVE DASHBOARD
A2: Real-time strategic overview of your writing career milestones, fictional universes, active pacing, and habit momentum.
A4: LIFETIME CAREER WORDS | C4: =UPPER(Config!$G$5)&" UNIVERSE" -> RELIQUARY UNIVERSE | E4: =UPPER(Config!$G$6)&" PROJECTS" -> STANDALONE PROJECTS | G4: TRAILING 30D VELOCITY
A5: =SUM('My Books'!$H$5:$H$24) -> 7450 | C5: =SUMIF('My Books'!$D$5:$D$24,Config!$G$5,'My Books'!$H$5:$H$24) -> 0 | E5: =SUMIF('My Books'!$D$5:$D$24,Config!$G$6,'My Books'!$H$5:$H$24) -> 0 | G5: =Calc!$S$11 -> 162
A6: ="(" & TEXT(IF(Config!$B$6>0, A5/Config!$B$6, 0), "0.0%") & " of " & TEXT(Config!$B$6/1000000, "#,##0") & "M Milestone)" -> (0.0% of 15M Milestone) | C6: ="(" & TEXT(IF(A5>0, C5/A5, 0), "0.0%") & " of Total Output)" -> (0.0% of Total Output) | E6: ="(" & TEXT(IF(A5>0, E5/A5, 0), "0.0%") & " of Total Output)" -> (0.0% of Total Output) | G6: Words / Day (Actual Pace)
A7: ="🔥 Streak: "&Calc!$S$8&IF(Calc!$S$8=1," day"," days")&" · "&Calc!$S$10&" grace left" -> 🔥 Streak: 2 days · 0 grace left | C7: ="🎯 Month Total: "&TEXT(Calc!$S$6,"#,##0")&" wds" -> 🎯 Month Total: 0 wds | E7: ="🏁 Month Target: "&TEXT(Calc!$S$5,"#,##0")&" wds" -> 🏁 Month Target: 62,000 wds | G7: ="📅 YTD: "&TEXT(Calc!$S$7,"#,##0")&" / "&TEXT(Config!$B$7,"#,##0")&" ("&TEXT(IF(Config!$B$7>0,Calc!$S$7/Config!$B$7,0),"0%")&")" -> 📅 YTD: 0 / 730,000 (0%)
A8: 📌 CURRENT ACTIVE BOOKS SPOTLIGHT (unfinished books, soonest deadline first)
A9: Book Title | B9: Universe | C9: Stage | D9: Draft Target Words | E9: Total Work Words | F9: Draft Progress % | G9: Days Left | H9: Draft Words/Day Needed | I9: Draft Words
A10: =IF(Calc!$P$5=0,"",INDEX('My Books'!$B$1:$B$24,Calc!$P$5)) -> Prisoner of Sand Sea | B10: =IF(Calc!$P$5=0,"",INDEX('My Books'!$D$1:$D$24,Calc!$P$5)) -> Reliquary | C10: =IF(Calc!$P$5=0,"",INDEX('My Books'!$F$1:$F$24,Calc!$P$5)) -> Concept | D10: =IF(Calc!$P$5=0,"",INDEX('My Books'!$G$1:$G$24,Calc!$P$5)) -> 200000 | E10: =IF(Calc!$P$5=0,"",INDEX('My Books'!$H$1:$H$24,Calc!$P$5)) -> 0 | F10: =IF(Calc!$P$5=0,"",INDEX('My Books'!$I$1:$I$24,Calc!$P$5)) -> 0 | G10: =IF(Calc!$P$5=0,"",INDEX('My Books'!$M$1:$M$24,Calc!$P$5)) -> 257 | H10: =IF(Calc!$P$5=0,"",INDEX('My Books'!$N$1:$N$24,Calc!$P$5)) -> 1105 | I10: =IF(Calc!$P$5=0,"",INDEX('My Books'!$Q$1:$Q$24,Calc!$P$5)) -> 0
A11: =IF(Calc!$P$6=0,"",INDEX('My Books'!$B$1:$B$24,Calc!$P$6)) -> Gothic Fantasy 1 | B11: =IF(Calc!$P$6=0,"",INDEX('My Books'!$D$1:$D$24,Calc!$P$6)) -> Reliquary | C11: =IF(Calc!$P$6=0,"",INDEX('My Books'!$F$1:$F$24,Calc!$P$6)) -> Concept | D11: =IF(Calc!$P$6=0,"",INDEX('My Books'!$G$1:$G$24,Calc!$P$6)) -> 150000 | E11: =IF(Calc!$P$6=0,"",INDEX('My Books'!$H$1:$H$24,Calc!$P$6)) -> 0 | F11: =IF(Calc!$P$6=0,"",INDEX('My Books'!$I$1:$I$24,Calc!$P$6)) -> 0 | G11: =IF(Calc!$P$6=0,"",INDEX('My Books'!$M$1:$M$24,Calc!$P$6)) -> 441 | H11: =IF(Calc!$P$6=0,"",INDEX('My Books'!$N$1:$N$24,Calc!$P$6)) -> 816 | I11: =IF(Calc!$P$6=0,"",INDEX('My Books'!$Q$1:$Q$24,Calc!$P$6)) -> 0
A12: =IF(Calc!$P$7=0,"",INDEX('My Books'!$B$1:$B$24,Calc!$P$7)) -> Quest Fantasy 1 | B12: =IF(Calc!$P$7=0,"",INDEX('My Books'!$D$1:$D$24,Calc!$P$7)) -> Reliquary | C12: =IF(Calc!$P$7=0,"",INDEX('My Books'!$F$1:$F$24,Calc!$P$7)) -> Concept | D12: =IF(Calc!$P$7=0,"",INDEX('My Books'!$G$1:$G$24,Calc!$P$7)) -> 200000 | E12: =IF(Calc!$P$7=0,"",INDEX('My Books'!$H$1:$H$24,Calc!$P$7)) -> 0 | F12: =IF(Calc!$P$7=0,"",INDEX('My Books'!$I$1:$I$24,Calc!$P$7)) -> 0 | G12: =IF(Calc!$P$7=0,"",INDEX('My Books'!$M$1:$M$24,Calc!$P$7)) -> 562 | H12: =IF(Calc!$P$7=0,"",INDEX('My Books'!$N$1:$N$24,Calc!$P$7)) -> 1653 | I12: =IF(Calc!$P$7=0,"",INDEX('My Books'!$Q$1:$Q$24,Calc!$P$7)) -> 0
A13: =IF(Calc!$P$8=0,"",INDEX('My Books'!$B$1:$B$24,Calc!$P$8)) -> Ruler of Sand Sea | B13: =IF(Calc!$P$8=0,"",INDEX('My Books'!$D$1:$D$24,Calc!$P$8)) -> Reliquary | C13: =IF(Calc!$P$8=0,"",INDEX('My Books'!$F$1:$F$24,Calc!$P$8)) -> Concept | D13: =IF(Calc!$P$8=0,"",INDEX('My Books'!$G$1:$G$24,Calc!$P$8)) -> 200000 | E13: =IF(Calc!$P$8=0,"",INDEX('My Books'!$H$1:$H$24,Calc!$P$8)) -> 0 | F13: =IF(Calc!$P$8=0,"",INDEX('My Books'!$I$1:$I$24,Calc!$P$8)) -> 0 | G13: =IF(Calc!$P$8=0,"",INDEX('My Books'!$M$1:$M$24,Calc!$P$8)) -> 685 | H13: =IF(Calc!$P$8=0,"",INDEX('My Books'!$N$1:$N$24,Calc!$P$8)) -> 1627 | I13: =IF(Calc!$P$8=0,"",INDEX('My Books'!$Q$1:$Q$24,Calc!$P$8)) -> 0
A14: =IF(Calc!$P$9=0,"",INDEX('My Books'!$B$1:$B$24,Calc!$P$9)) -> Company of the Storm | B14: =IF(Calc!$P$9=0,"",INDEX('My Books'!$D$1:$D$24,Calc!$P$9)) -> Reliquary | C14: =IF(Calc!$P$9=0,"",INDEX('My Books'!$F$1:$F$24,Calc!$P$9)) -> Concept | D14: =IF(Calc!$P$9=0,"",INDEX('My Books'!$G$1:$G$24,Calc!$P$9)) -> 150000 | E14: =IF(Calc!$P$9=0,"",INDEX('My Books'!$H$1:$H$24,Calc!$P$9)) -> 0 | F14: =IF(Calc!$P$9=0,"",INDEX('My Books'!$I$1:$I$24,Calc!$P$9)) -> 0 | G14: =IF(Calc!$P$9=0,"",INDEX('My Books'!$M$1:$M$24,Calc!$P$9)) -> 807 | H14: =IF(Calc!$P$9=0,"",INDEX('My Books'!$N$1:$N$24,Calc!$P$9)) -> 1230 | I14: =IF(Calc!$P$9=0,"",INDEX('My Books'!$Q$1:$Q$24,Calc!$P$9)) -> 0
A15: =IF(Calc!$P$10=0,"",INDEX('My Books'!$B$1:$B$24,Calc!$P$10)) -> The Silver Chronicles | B15: =IF(Calc!$P$10=0,"",INDEX('My Books'!$D$1:$D$24,Calc!$P$10)) -> Eldoria-Cosmos | C15: =IF(Calc!$P$10=0,"",INDEX('My Books'!$F$1:$F$24,Calc!$P$10)) -> Drafting | D15: =IF(Calc!$P$10=0,"",INDEX('My Books'!$G$1:$G$24,Calc!$P$10)) -> 120000 | E15: =IF(Calc!$P$10=0,"",INDEX('My Books'!$H$1:$H$24,Calc!$P$10)) -> 7450 | F15: =IF(Calc!$P$10=0,"",INDEX('My Books'!$I$1:$I$24,Calc!$P$10)) -> 0.0475 | G15: =IF(Calc!$P$10=0,"",INDEX('My Books'!$M$1:$M$24,Calc!$P$10)) -> 227 | H15: =IF(Calc!$P$10=0,"",INDEX('My Books'!$N$1:$N$24,Calc!$P$10)) -> 0 | I15: =IF(Calc!$P$10=0,"",INDEX('My Books'!$Q$1:$Q$24,Calc!$P$10)) -> 5700
A16: =IF(Calc!$P$11=0,"",INDEX('My Books'!$B$1:$B$24,Calc!$P$11)) | B16: =IF(Calc!$P$11=0,"",INDEX('My Books'!$D$1:$D$24,Calc!$P$11)) | C16: =IF(Calc!$P$11=0,"",INDEX('My Books'!$F$1:$F$24,Calc!$P$11)) | D16: =IF(Calc!$P$11=0,"",INDEX('My Books'!$G$1:$G$24,Calc!$P$11)) | E16: =IF(Calc!$P$11=0,"",INDEX('My Books'!$H$1:$H$24,Calc!$P$11)) | F16: =IF(Calc!$P$11=0,"",INDEX('My Books'!$I$1:$I$24,Calc!$P$11)) | G16: =IF(Calc!$P$11=0,"",INDEX('My Books'!$M$1:$M$24,Calc!$P$11)) | H16: =IF(Calc!$P$11=0,"",INDEX('My Books'!$N$1:$N$24,Calc!$P$11)) | I16: =IF(Calc!$P$11=0,"",INDEX('My Books'!$Q$1:$Q$24,Calc!$P$11))
A17: =IF(Calc!$P$12=0,"",INDEX('My Books'!$B$1:$B$24,Calc!$P$12)) | B17: =IF(Calc!$P$12=0,"",INDEX('My Books'!$D$1:$D$24,Calc!$P$12)) | C17: =IF(Calc!$P$12=0,"",INDEX('My Books'!$F$1:$F$24,Calc!$P$12)) | D17: =IF(Calc!$P$12=0,"",INDEX('My Books'!$G$1:$G$24,Calc!$P$12)) | E17: =IF(Calc!$P$12=0,"",INDEX('My Books'!$H$1:$H$24,Calc!$P$12)) | F17: =IF(Calc!$P$12=0,"",INDEX('My Books'!$I$1:$I$24,Calc!$P$12)) | G17: =IF(Calc!$P$12=0,"",INDEX('My Books'!$M$1:$M$24,Calc!$P$12)) | H17: =IF(Calc!$P$12=0,"",INDEX('My Books'!$N$1:$N$24,Calc!$P$12)) | I17: =IF(Calc!$P$12=0,"",INDEX('My Books'!$Q$1:$Q$24,Calc!$P$12))
A18: 💡 QUICK USER GUIDE & BEST PRACTICES
A19: 1. Adding Projects | B19: Add projects in 'My Books' or run `python scripts/arcanum workbook sync`: Year, Type, Universe, Stage, Continuity Compilers, World Bible Lore, and all 15 charts across the 8 sheets auto-update dynamically!
A20: 2. Series Dropdown | B20: Add series in 'Universes & Series': Universe auto-populates, and the Series Canon & Word Volume charts below the table update automatically.
A21: 3. Daily Logging | B21: In 'Daily Writing Log', select a Date and Book Title — Stage at Session auto-populates from 'My Books', and Creative Phase & Weekly Rhythm charts update live.
A22: 4. Phase-Aware Effort | B22: Effort multipliers in 'Config' weight each session by its logged stage (100% for drafting/in-phase outlining, 50% for worldbuilding, 20% for in-phase revision, 0% for premature revision during drafting).
A23: 5. Central Settings | B23: Adjust the daily effort goal, lifetime word milestone, annual production target, and phase-effort weights in 'Config'. The monthly target automatically scales to the exact number of days in the current month.
A25: 📈 EXECUTIVE VISUAL TELEMETRY • 30D VELOCITY, ACTIVE SPOTLIGHT & MULTI-YEAR CAPACITY

Sheet Config
A1: ⚙️ ECOSYSTEM CONFIGURATION & CENTRAL SETTINGS
A2: =TODAY() -> 46312 | B2: System Reference Date (Centralized TODAY() for all pace & projection formulas)
A4: Variable Name | B4: Value | C4: Unit / Description | E4: Book Types | F4: Project Stages | G4: Universes | I4: =IF(Dashboard!$A$10="","Project 1: (empty slot)","Project 1: "&Dashboard!$A$10) -> Project 1: Prisoner of Sand Sea | J4: Words | K4: Share | M4: =IF(Dashboard!$A$14="","Project 5: (empty slot)","Project 5: "&Dashboard!$A$14) -> Project 5: Company of the Storm | N4: Words | O4: Share
A5: Daily Effort Goal Target | B5: 2000 | C5: Weighted effort points per day | E5: Novel | F5: Concept | G5: Reliquary | I5: Draft Words | J5: =N(Dashboard!$I$10) -> 0 | K5: =IF(N(Dashboard!$D$10)>0,J5/Dashboard!$D$10,0) -> 0 | M5: Draft Words | N5: =N(Dashboard!$I$14) -> 0 | O5: =IF(N(Dashboard!$D$14)>0,N5/Dashboard!$D$14,0) -> 0
A6: Career Lifetime Milestone Target | B6: 15000000 | C6: Total Lifetime Words goal | E6: Novella | F6: Pre-Draft Outline | G6: Standalone | I6: Remaining | J6: =MAX(0,N(Dashboard!$D$10)-J5) -> 200000 | K6: =IF(N(Dashboard!$D$10)>0,J6/Dashboard!$D$10,0) -> 1 | M6: Remaining | N6: =MAX(0,N(Dashboard!$D$14)-N5) -> 150000 | O6: =IF(N(Dashboard!$D$14)>0,N6/Dashboard!$D$14,0) -> 1
A7: Current Annual Production Target | B7: 730000 | C7: Target words for current year | E7: Novelette | F7: Drafting | G7: Eldoria-Cosmos
A8: Streak Grace Days / Month | B8: 3 | C8: Forgiven missed days per month (assumption: 3) | E8: Short Story | F8: Pre-Revision Outline | G8: Other Universe | I8: =IF(Dashboard!$A$11="","Project 2: (empty slot)","Project 2: "&Dashboard!$A$11) -> Project 2: Gothic Fantasy 1 | J8: Words | K8: Share | M8: =IF(Dashboard!$A$15="","Project 6: (empty slot)","Project 6: "&Dashboard!$A$15) -> Project 6: The Silver Chronicles | N8: Words | O8: Share
A9: Effort Multiplier (Phase Weight) | B9: Weight | C9: Rule / Application Logic | E9: Anthology / Omnibus | F9: Revision | I9: Draft Words | J9: =N(Dashboard!$I$11) -> 0 | K9: =IF(N(Dashboard!$D$11)>0,J9/Dashboard!$D$11,0) -> 0 | M9: Draft Words | N9: =N(Dashboard!$I$15) -> 5700 | O9: =IF(N(Dashboard!$D$15)>0,N9/Dashboard!$D$15,0) -> 0.0475
A10: Drafting Prose (First Draft) | B10: 1 | C10: Always 100% effort credit toward daily goal | F10: Beta Review | I10: Remaining | J10: =MAX(0,N(Dashboard!$D$11)-J9) -> 150000 | K10: =IF(N(Dashboard!$D$11)>0,J10/Dashboard!$D$11,0) -> 1 | M10: Remaining | N10: =MAX(0,N(Dashboard!$D$15)-N9) -> 114300 | O10: =IF(N(Dashboard!$D$15)>0,N10/Dashboard!$D$15,0) -> 0.9525
A11: Pre-Draft Outlining | B11: 1 | C11: Full 100% credit when book is in Pre-Draft Outline stage | F11: Proofing
A12: Pre-Revision Outlining | B12: 1 | C12: Full 100% credit when book is in Pre-Revision Outline stage | F12: Querying | I12: =IF(Dashboard!$A$12="","Project 3: (empty slot)","Project 3: "&Dashboard!$A$12) -> Project 3: Quest Fantasy 1 | J12: Words | K12: Share | M12: =IF(Dashboard!$A$16="","Project 7: (empty slot)","Project 7: "&Dashboard!$A$16) -> Project 7: (empty slot) | N12: Words | O12: Share
A13: Off-Phase Outlining | B13: 0.5 | C13: Half credit if outlining outside designated outline stages | F13: Publishing | I13: Draft Words | J13: =N(Dashboard!$I$12) -> 0 | K13: =IF(N(Dashboard!$D$12)>0,J13/Dashboard!$D$12,0) -> 0 | M13: Draft Words | N13: =N(Dashboard!$I$16) -> 0 | O13: =IF(N(Dashboard!$D$16)>0,N13/Dashboard!$D$16,0) -> 0
A14: Worldbuilding / Lore Notes | B14: 0.5 | C14: 50% credit (2 worldbuilding words = 1 effort point) | F14: Published | I14: Remaining | J14: =MAX(0,N(Dashboard!$D$12)-J13) -> 200000 | K14: =IF(N(Dashboard!$D$12)>0,J14/Dashboard!$D$12,0) -> 1 | M14: Remaining | N14: =MAX(0,N(Dashboard!$D$16)-N13) -> 0 | O14: =IF(N(Dashboard!$D$16)>0,N14/Dashboard!$D$16,0) -> 0
A15: Revisions (during Revision Stage) | B15: 0.2 | C15: 20% credit when book is in Revision stage (5 revised wds = 1 pt)
A16: Revisions (outside Revision Stage) | B16: 0 | C16: Zero effort credit during drafting (prevents premature editing!) | I16: =IF(Dashboard!$A$13="","Project 4: (empty slot)","Project 4: "&Dashboard!$A$13) -> Project 4: Ruler of Sand Sea | J16: Words | K16: Share | M16: =IF(Dashboard!$A$17="","Project 8: (empty slot)","Project 8: "&Dashboard!$A$17) -> Project 8: (empty slot) | N16: Words | O16: Share
I17: Draft Words | J17: =N(Dashboard!$I$13) -> 0 | K17: =IF(N(Dashboard!$D$13)>0,J17/Dashboard!$D$13,0) -> 0 | M17: Draft Words | N17: =N(Dashboard!$I$17) -> 0 | O17: =IF(N(Dashboard!$D$17)>0,N17/Dashboard!$D$17,0) -> 0
I18: Remaining | J18: =MAX(0,N(Dashboard!$D$13)-J17) -> 200000 | K18: =IF(N(Dashboard!$D$13)>0,J18/Dashboard!$D$13,0) -> 1 | M18: Remaining | N18: =MAX(0,N(Dashboard!$D$17)-N17) -> 0 | O18: =IF(N(Dashboard!$D$17)>0,N18/Dashboard!$D$17,0) -> 0
I20: Daily Habit Progress | J20: Effort Points | K20: Share
I21: Earned Today | J21: =SUMIFS('Daily Writing Log'!$I$5:$I$34,'Daily Writing Log'!$A$5:$A$34,$A$2) -> 0 | K21: =IF(Config!$B$5>0,MIN(1,J21/Config!$B$5),0) -> 0
I22: Remaining Today | J22: =MAX(0,$B$5-J21) -> 2000 | K22: =IF(Config!$B$5>0,MAX(0,1-J21/Config!$B$5),0) -> 1
A24: 🩺 DATA INTEGRITY CHECKS | B24: Issues | C24: What it means / how to fix
A25: Log rows with unknown Book Title | B25: =SUMPRODUCT(('Daily Writing Log'!$B$5:$B$34<>"")*(COUNTIF('My Books'!$B$5:$B$24,'Daily Writing Log'!$B$5:$B$34)=0)) -> 0 | C25: Title not found in 'My Books' (typo or renamed book) - its words are not counted toward any book
A26: Duplicate Book Titles | B26: =SUMPRODUCT(('My Books'!$B$5:$B$24<>"")*(COUNTIF('My Books'!$B$5:$B$24,'My Books'!$B$5:$B$24)>1)) -> 0 | C26: Titles must be unique - duplicates double-count words
A27: Log rows missing a Stage | B27: =SUMPRODUCT(('Daily Writing Log'!$B$5:$B$34<>"")*('Daily Writing Log'!$C$5:$C$34="")) -> 0 | C27: Stage drives effort weights (outlining / revision) - pick one in the Stage column
A28: Log rows with words dated in the future | B28: =COUNTIFS('Daily Writing Log'!$A$5:$A$34,">"&$A$2,'Daily Writing Log'!$H$5:$H$34,">0") -> 1 | C28: Future-dated word counts do not count toward today / streak / velocity (0-word planning rows are ignored)
A29: Log rows missing Date or Book | B29: =SUMPRODUCT((('Daily Writing Log'!$D$5:$D$34+'Daily Writing Log'!$E$5:$E$34+'Daily Writing Log'!$F$5:$F$34+'Daily Writing Log'!$G$5:$G$34)>0)*(('Daily Writing Log'!$A$5:$A$34="")+('Daily Writing Log'!$B$5:$B$34="")>0)) -> 0 | C29: Words without a date and a book are invisible to the dashboard
A30: Words not credited to any book | B30: =SUM('Daily Writing Log'!$H$5:$H$34)-SUM('My Books'!$H$5:$H$24) -> 0 | C30: Should be 0. Non-zero = orphaned log rows (see first check)
A31: Series catalog errors or unknown series | B31: =COUNTIF('Universes & Series'!$H$5:$H$24,"⚠*")+SUMPRODUCT(('My Books'!$E$5:$E$24<>"")*(COUNTIF('Universes & Series'!$A$5:$A$24,'My Books'!$E$5:$E$24)=0)) -> 0 | C31: Flags if 'My Books' uses an unknown Series or if cataloged books exceed Planned Books in 'Universes & Series'
A32: Active books past deadline (Overdue) | B32: =COUNTIF('My Books'!$R$5:$R$24,"🔴 Overdue") -> 0 | C32: Unfinished books in 'My Books' whose deadline has passed — extend deadline or prioritize
A33: Overall status | B33: =COUNTIF(B25:B32,"<>0") -> 1 | C33: =IF(B33=0,"✅ All 8 integrity checks pass","⚠️ "&B33&" check(s) need attention") -> ⚠️ 1 check(s) need attention

Sheet Universes & Series
A1: 🌌 UNIVERSES & SERIES • CANON PORTFOLIO
A2: Manage shared fictional universes alongside standalone stories and track lifetime wordcounts across each series.
A4: Series Title | B4: Universe | C4: Planned Books | D4: Completed Books | E4: Books In Progress | F4: Total Work Words | G4: Series Premise / Notes | H4: Catalog Check | I4: Draft Progress %
A5: Sand Sea Saga | B5: Reliquary | C5: 3 | D5: =IF(A5="","",COUNTIFS('My Books'!$E$5:$E$24,A5,'My Books'!$F$5:$F$24,"Published")) -> 0 | E5: =IF(A5="","",COUNTIFS('My Books'!$E$5:$E$24,A5,'My Books'!$F$5:$F$24,"<>Published",'My Books'!$F$5:$F$24,"<>")) -> 2 | F5: =IF(A5="","",SUMIFS('My Books'!$H$5:$H$24,'My Books'!$E$5:$E$24,A5)) -> 0 | G5: Cosmere inspired dark-epic fantasy | H5: =IF(A5="","",IF(D5+E5>C5,"⚠️ Over-cataloged ("&(D5+E5)&"/"&C5&")","✓ "&(D5+E5)&" of "&C5&" cataloged ("&(C5-D5-E5)&" future)")) -> ✓ 2 of 3 cataloged (1 future) | I5: =IF(A5="","",IFERROR(SUMIFS('My Books'!$Q$5:$Q$24,'My Books'!$E$5:$E$24,A5)/SUMIFS('My Books'!$G$5:$G$24,'My Books'!$E$5:$E$24,A5),0)) -> 0
A6: Gothic Fantasy Series | B6: Reliquary | C6: 4 | D6: =IF(A6="","",COUNTIFS('My Books'!$E$5:$E$24,A6,'My Books'!$F$5:$F$24,"Published")) -> 0 | E6: =IF(A6="","",COUNTIFS('My Books'!$E$5:$E$24,A6,'My Books'!$F$5:$F$24,"<>Published",'My Books'!$F$5:$F$24,"<>")) -> 1 | F6: =IF(A6="","",SUMIFS('My Books'!$H$5:$H$24,'My Books'!$E$5:$E$24,A6)) -> 0 | G6: Bloodborne inspired grim-epic fantasy | H6: =IF(A6="","",IF(D6+E6>C6,"⚠️ Over-cataloged ("&(D6+E6)&"/"&C6&")","✓ "&(D6+E6)&" of "&C6&" cataloged ("&(C6-D6-E6)&" future)")) -> ✓ 1 of 4 cataloged (3 future) | I6: =IF(A6="","",IFERROR(SUMIFS('My Books'!$Q$5:$Q$24,'My Books'!$E$5:$E$24,A6)/SUMIFS('My Books'!$G$5:$G$24,'My Books'!$E$5:$E$24,A6),0)) -> 0
A7: Classic Quest Fantasy | B7: Reliquary | C7: 3 | D7: =IF(A7="","",COUNTIFS('My Books'!$E$5:$E$24,A7,'My Books'!$F$5:$F$24,"Published")) -> 0 | E7: =IF(A7="","",COUNTIFS('My Books'!$E$5:$E$24,A7,'My Books'!$F$5:$F$24,"<>Published",'My Books'!$F$5:$F$24,"<>")) -> 1 | F7: =IF(A7="","",SUMIFS('My Books'!$H$5:$H$24,'My Books'!$E$5:$E$24,A7)) -> 0 | G7: Golden age quest fantasy | H7: =IF(A7="","",IF(D7+E7>C7,"⚠️ Over-cataloged ("&(D7+E7)&"/"&C7&")","✓ "&(D7+E7)&" of "&C7&" cataloged ("&(C7-D7-E7)&" future)")) -> ✓ 1 of 3 cataloged (2 future) | I7: =IF(A7="","",IFERROR(SUMIFS('My Books'!$Q$5:$Q$24,'My Books'!$E$5:$E$24,A7)/SUMIFS('My Books'!$G$5:$G$24,'My Books'!$E$5:$E$24,A7),0)) -> 0
A8: Stormbreaker Chronicles | B8: Reliquary | C8: 8 | D8: =IF(A8="","",COUNTIFS('My Books'!$E$5:$E$24,A8,'My Books'!$F$5:$F$24,"Published")) -> 0 | E8: =IF(A8="","",COUNTIFS('My Books'!$E$5:$E$24,A8,'My Books'!$F$5:$F$24,"<>Published",'My Books'!$F$5:$F$24,"<>")) -> 1 | F8: =IF(A8="","",SUMIFS('My Books'!$H$5:$H$24,'My Books'!$E$5:$E$24,A8)) -> 0 | G8: Comedic adventures of a mercenary company | H8: =IF(A8="","",IF(D8+E8>C8,"⚠️ Over-cataloged ("&(D8+E8)&"/"&C8&")","✓ "&(D8+E8)&" of "&C8&" cataloged ("&(C8-D8-E8)&" future)")) -> ✓ 1 of 8 cataloged (7 future) | I8: =IF(A8="","",IFERROR(SUMIFS('My Books'!$Q$5:$Q$24,'My Books'!$E$5:$E$24,A8)/SUMIFS('My Books'!$G$5:$G$24,'My Books'!$E$5:$E$24,A8),0)) -> 0
A9: The Silver Chronicles | B9: Eldoria-Cosmos | C9: 3 | D9: =IF(A9="","",COUNTIFS('My Books'!$E$5:$E$24,A9,'My Books'!$F$5:$F$24,"Published")) -> 0 | E9: =IF(A9="","",COUNTIFS('My Books'!$E$5:$E$24,A9,'My Books'!$F$5:$F$24,"<>Published",'My Books'!$F$5:$F$24,"<>")) -> 1 | F9: =IF(A9="","",SUMIFS('My Books'!$H$5:$H$24,'My Books'!$E$5:$E$24,A9)) -> 7450 | G9: Sovereign multi-POV epic fantasy showcase (templates/demo-cosmos/Eldoria-Cosmos) | H9: =IF(A9="","",IF(D9+E9>C9,"⚠️ Over-cataloged ("&(D9+E9)&"/"&C9&")","✓ "&(D9+E9)&" of "&C9&" cataloged ("&(C9-D9-E9)&" future)")) -> ✓ 1 of 3 cataloged (2 future) | I9: =IF(A9="","",IFERROR(SUMIFS('My Books'!$Q$5:$Q$24,'My Books'!$E$5:$E$24,A9)/SUMIFS('My Books'!$G$5:$G$24,'My Books'!$E$5:$E$24,A9),0)) -> 0.0475
A10: Silver Chronicles | B10: Eldoria-Cosmos | C10: 3 | D10: =IF(A10="","",COUNTIFS('My Books'!$E$5:$E$24,A10,'My Books'!$F$5:$F$24,"Published")) -> 0 | E10: =IF(A10="","",COUNTIFS('My Books'!$E$5:$E$24,A10,'My Books'!$F$5:$F$24,"<>Published",'My Books'!$F$5:$F$24,"<>")) -> 0 | F10: =IF(A10="","",SUMIFS('My Books'!$H$5:$H$24,'My Books'!$E$5:$E$24,A10)) -> 0 | G10: Auto-registered series from sprint log (The Silver Chronicles) | H10: =IF(A10="","",IF(D10+E10>C10,"⚠️ Over-cataloged ("&(D10+E10)&"/"&C10&")","✓ "&(D10+E10)&" of "&C10&" cataloged ("&(C10-D10-E10)&" future)")) -> ✓ 0 of 3 cataloged (3 future) | I10: =IF(A10="","",IFERROR(SUMIFS('My Books'!$Q$5:$Q$24,'My Books'!$E$5:$E$24,A10)/SUMIFS('My Books'!$G$5:$G$24,'My Books'!$E$5:$E$24,A10),0)) -> 0
B11: =IF($A11="","",Config!$G$5) | D11: =IF($A11="","",COUNTIFS('My Books'!$E$5:$E$24,$A11,'My Books'!$F$5:$F$24,"Published")) | E11: =IF($A11="","",COUNTIFS('My Books'!$E$5:$E$24,$A11,'My Books'!$F$5:$F$24,"<>Published",'My Books'!$B$5:$B$24,"<>")) | F11: =IF($A11="","",SUMIF('My Books'!$E$5:$E$24,$A11,'My Books'!$H$5:$H$24)) | H11: =IF($A11="","",IF(OR($C11="",$C11<=0),"⚠ Set planned count",IF(COUNTIF('My Books'!$E$5:$E$24,$A11)=0,"⚠ No books cataloged",IF(COUNTIF('My Books'!$E$5:$E$24,$A11)=$C11,"✓ All "&$C11&" planned books cataloged",IF(COUNTIF('My Books'!$E$5:$E$24,$A11)<$C11,"✓ "&COUNTIF('My Books'!$E$5:$E$24,$A11)&" of "&$C11&" cataloged ("&($C11-COUNTIF('My Books'!$E$5:$E$24,$A11))&" future)","⚠ More cataloged than planned"))))) | I11: =IF($A11="","",IF(SUMIF('My Books'!$E$5:$E$24,$A11,'My Books'!$G$5:$G$24)>0,SUMIF('My Books'!$E$5:$E$24,$A11,'My Books'!$Q$5:$Q$24)/SUMIF('My Books'!$E$5:$E$24,$A11,'My Books'!$G$5:$G$24),0))
B12: =IF($A12="","",Config!$G$5) | D12: =IF($A12="","",COUNTIFS('My Books'!$E$5:$E$24,$A12,'My Books'!$F$5:$F$24,"Published")) | E12: =IF($A12="","",COUNTIFS('My Books'!$E$5:$E$24,$A12,'My Books'!$F$5:$F$24,"<>Published",'My Books'!$B$5:$B$24,"<>")) | F12: =IF($A12="","",SUMIF('My Books'!$E$5:$E$24,$A12,'My Books'!$H$5:$H$24)) | H12: =IF($A12="","",IF(OR($C12="",$C12<=0),"⚠ Set planned count",IF(COUNTIF('My Books'!$E$5:$E$24,$A12)=0,"⚠ No books cataloged",IF(COUNTIF('My Books'!$E$5:$E$24,$A12)=$C12,"✓ All "&$C12&" planned books cataloged",IF(COUNTIF('My Books'!$E$5:$E$24,$A12)<$C12,"✓ "&COUNTIF('My Books'!$E$5:$E$24,$A12)&" of "&$C12&" cataloged ("&($C12-COUNTIF('My Books'!$E$5:$E$24,$A12))&" future)","⚠ More cataloged than planned"))))) | I12: =IF($A12="","",IF(SUMIF('My Books'!$E$5:$E$24,$A12,'My Books'!$G$5:$G$24)>0,SUMIF('My Books'!$E$5:$E$24,$A12,'My Books'!$Q$5:$Q$24)/SUMIF('My Books'!$E$5:$E$24,$A12,'My Books'!$G$5:$G$24),0))
B13: =IF($A13="","",Config!$G$5) | D13: =IF($A13="","",COUNTIFS('My Books'!$E$5:$E$24,$A13,'My Books'!$F$5:$F$24,"Published")) | E13: =IF($A13="","",COUNTIFS('My Books'!$E$5:$E$24,$A13,'My Books'!$F$5:$F$24,"<>Published",'My Books'!$B$5:$B$24,"<>")) | F13: =IF($A13="","",SUMIF('My Books'!$E$5:$E$24,$A13,'My Books'!$H$5:$H$24)) | H13: =IF($A13="","",IF(OR($C13="",$C13<=0),"⚠ Set planned count",IF(COUNTIF('My Books'!$E$5:$E$24,$A13)=0,"⚠ No books cataloged",IF(COUNTIF('My Books'!$E$5:$E$24,$A13)=$C13,"✓ All "&$C13&" planned books cataloged",IF(COUNTIF('My Books'!$E$5:$E$24,$A13)<$C13,"✓ "&COUNTIF('My Books'!$E$5:$E$24,$A13)&" of "&$C13&" cataloged ("&($C13-COUNTIF('My Books'!$E$5:$E$24,$A13))&" future)","⚠ More cataloged than planned"))))) | I13: =IF($A13="","",IF(SUMIF('My Books'!$E$5:$E$24,$A13,'My Books'!$G$5:$G$24)>0,SUMIF('My Books'!$E$5:$E$24,$A13,'My Books'!$Q$5:$Q$24)/SUMIF('My Books'!$E$5:$E$24,$A13,'My Books'!$G$5:$G$24),0))
B14: =IF($A14="","",Config!$G$5) | D14: =IF($A14="","",COUNTIFS('My Books'!$E$5:$E$24,$A14,'My Books'!$F$5:$F$24,"Published")) | E14: =IF($A14="","",COUNTIFS('My Books'!$E$5:$E$24,$A14,'My Books'!$F$5:$F$24,"<>Published",'My Books'!$B$5:$B$24,"<>")) | F14: =IF($A14="","",SUMIF('My Books'!$E$5:$E$24,$A14,'My Books'!$H$5:$H$24)) | H14: =IF($A14="","",IF(OR($C14="",$C14<=0),"⚠ Set planned count",IF(COUNTIF('My Books'!$E$5:$E$24,$A14)=0,"⚠ No books cataloged",IF(COUNTIF('My Books'!$E$5:$E$24,$A14)=$C14,"✓ All "&$C14&" planned books cataloged",IF(COUNTIF('My Books'!$E$5:$E$24,$A14)<$C14,"✓ "&COUNTIF('My Books'!$E$5:$E$24,$A14)&" of "&$C14&" cataloged ("&($C14-COUNTIF('My Books'!$E$5:$E$24,$A14))&" future)","⚠ More cataloged than planned"))))) | I14: =IF($A14="","",IF(SUMIF('My Books'!$E$5:$E$24,$A14,'My Books'!$G$5:$G$24)>0,SUMIF('My Books'!$E$5:$E$24,$A14,'My Books'!$Q$5:$Q$24)/SUMIF('My Books'!$E$5:$E$24,$A14,'My Books'!$G$5:$G$24),0))
B15: =IF($A15="","",Config!$G$5) | D15: =IF($A15="","",COUNTIFS('My Books'!$E$5:$E$24,$A15,'My Books'!$F$5:$F$24,"Published")) | E15: =IF($A15="","",COUNTIFS('My Books'!$E$5:$E$24,$A15,'My Books'!$F$5:$F$24,"<>Published",'My Books'!$B$5:$B$24,"<>")) | F15: =IF($A15="","",SUMIF('My Books'!$E$5:$E$24,$A15,'My Books'!$H$5:$H$24)) | H15: =IF($A15="","",IF(OR($C15="",$C15<=0),"⚠ Set planned count",IF(COUNTIF('My Books'!$E$5:$E$24,$A15)=0,"⚠ No books cataloged",IF(COUNTIF('My Books'!$E$5:$E$24,$A15)=$C15,"✓ All "&$C15&" planned books cataloged",IF(COUNTIF('My Books'!$E$5:$E$24,$A15)<$C15,"✓ "&COUNTIF('My Books'!$E$5:$E$24,$A15)&" of "&$C15&" cataloged ("&($C15-COUNTIF('My Books'!$E$5:$E$24,$A15))&" future)","⚠ More cataloged than planned"))))) | I15: =IF($A15="","",IF(SUMIF('My Books'!$E$5:$E$24,$A15,'My Books'!$G$5:$G$24)>0,SUMIF('My Books'!$E$5:$E$24,$A15,'My Books'!$Q$5:$Q$24)/SUMIF('My Books'!$E$5:$E$24,$A15,'My Books'!$G$5:$G$24),0))
B16: =IF($A16="","",Config!$G$5) | D16: =IF($A16="","",COUNTIFS('My Books'!$E$5:$E$24,$A16,'My Books'!$F$5:$F$24,"Published")) | E16: =IF($A16="","",COUNTIFS('My Books'!$E$5:$E$24,$A16,'My Books'!$F$5:$F$24,"<>Published",'My Books'!$B$5:$B$24,"<>")) | F16: =IF($A16="","",SUMIF('My Books'!$E$5:$E$24,$A16,'My Books'!$H$5:$H$24)) | H16: =IF($A16="","",IF(OR($C16="",$C16<=0),"⚠ Set planned count",IF(COUNTIF('My Books'!$E$5:$E$24,$A16)=0,"⚠ No books cataloged",IF(COUNTIF('My Books'!$E$5:$E$24,$A16)=$C16,"✓ All "&$C16&" planned books cataloged",IF(COUNTIF('My Books'!$E$5:$E$24,$A16)<$C16,"✓ "&COUNTIF('My Books'!$E$5:$E$24,$A16)&" of "&$C16&" cataloged ("&($C16-COUNTIF('My Books'!$E$5:$E$24,$A16))&" future)","⚠ More cataloged than planned"))))) | I16: =IF($A16="","",IF(SUMIF('My Books'!$E$5:$E$24,$A16,'My Books'!$G$5:$G$24)>0,SUMIF('My Books'!$E$5:$E$24,$A16,'My Books'!$Q$5:$Q$24)/SUMIF('My Books'!$E$5:$E$24,$A16,'My Books'!$G$5:$G$24),0))
B17: =IF($A17="","",Config!$G$5) | D17: =IF($A17="","",COUNTIFS('My Books'!$E$5:$E$24,$A17,'My Books'!$F$5:$F$24,"Published")) | E17: =IF($A17="","",COUNTIFS('My Books'!$E$5:$E$24,$A17,'My Books'!$F$5:$F$24,"<>Published",'My Books'!$B$5:$B$24,"<>")) | F17: =IF($A17="","",SUMIF('My Books'!$E$5:$E$24,$A17,'My Books'!$H$5:$H$24)) | H17: =IF($A17="","",IF(OR($C17="",$C17<=0),"⚠ Set planned count",IF(COUNTIF('My Books'!$E$5:$E$24,$A17)=0,"⚠ No books cataloged",IF(COUNTIF('My Books'!$E$5:$E$24,$A17)=$C17,"✓ All "&$C17&" planned books cataloged",IF(COUNTIF('My Books'!$E$5:$E$24,$A17)<$C17,"✓ "&COUNTIF('My Books'!$E$5:$E$24,$A17)&" of "&$C17&" cataloged ("&($C17-COUNTIF('My Books'!$E$5:$E$24,$A17))&" future)","⚠ More cataloged than planned"))))) | I17: =IF($A17="","",IF(SUMIF('My Books'!$E$5:$E$24,$A17,'My Books'!$G$5:$G$24)>0,SUMIF('My Books'!$E$5:$E$24,$A17,'My Books'!$Q$5:$Q$24)/SUMIF('My Books'!$E$5:$E$24,$A17,'My Books'!$G$5:$G$24),0))
B18: =IF($A18="","",Config!$G$5) | D18: =IF($A18="","",COUNTIFS('My Books'!$E$5:$E$24,$A18,'My Books'!$F$5:$F$24,"Published")) | E18: =IF($A18="","",COUNTIFS('My Books'!$E$5:$E$24,$A18,'My Books'!$F$5:$F$24,"<>Published",'My Books'!$B$5:$B$24,"<>")) | F18: =IF($A18="","",SUMIF('My Books'!$E$5:$E$24,$A18,'My Books'!$H$5:$H$24)) | H18: =IF($A18="","",IF(OR($C18="",$C18<=0),"⚠ Set planned count",IF(COUNTIF('My Books'!$E$5:$E$24,$A18)=0,"⚠ No books cataloged",IF(COUNTIF('My Books'!$E$5:$E$24,$A18)=$C18,"✓ All "&$C18&" planned books cataloged",IF(COUNTIF('My Books'!$E$5:$E$24,$A18)<$C18,"✓ "&COUNTIF('My Books'!$E$5:$E$24,$A18)&" of "&$C18&" cataloged ("&($C18-COUNTIF('My Books'!$E$5:$E$24,$A18))&" future)","⚠ More cataloged than planned"))))) | I18: =IF($A18="","",IF(SUMIF('My Books'!$E$5:$E$24,$A18,'My Books'!$G$5:$G$24)>0,SUMIF('My Books'!$E$5:$E$24,$A18,'My Books'!$Q$5:$Q$24)/SUMIF('My Books'!$E$5:$E$24,$A18,'My Books'!$G$5:$G$24),0))
B19: =IF($A19="","",Config!$G$5) | D19: =IF($A19="","",COUNTIFS('My Books'!$E$5:$E$24,$A19,'My Books'!$F$5:$F$24,"Published")) | E19: =IF($A19="","",COUNTIFS('My Books'!$E$5:$E$24,$A19,'My Books'!$F$5:$F$24,"<>Published",'My Books'!$B$5:$B$24,"<>")) | F19: =IF($A19="","",SUMIF('My Books'!$E$5:$E$24,$A19,'My Books'!$H$5:$H$24)) | H19: =IF($A19="","",IF(OR($C19="",$C19<=0),"⚠ Set planned count",IF(COUNTIF('My Books'!$E$5:$E$24,$A19)=0,"⚠ No books cataloged",IF(COUNTIF('My Books'!$E$5:$E$24,$A19)=$C19,"✓ All "&$C19&" planned books cataloged",IF(COUNTIF('My Books'!$E$5:$E$24,$A19)<$C19,"✓ "&COUNTIF('My Books'!$E$5:$E$24,$A19)&" of "&$C19&" cataloged ("&($C19-COUNTIF('My Books'!$E$5:$E$24,$A19))&" future)","⚠ More cataloged than planned"))))) | I19: =IF($A19="","",IF(SUMIF('My Books'!$E$5:$E$24,$A19,'My Books'!$G$5:$G$24)>0,SUMIF('My Books'!$E$5:$E$24,$A19,'My Books'!$Q$5:$Q$24)/SUMIF('My Books'!$E$5:$E$24,$A19,'My Books'!$G$5:$G$24),0))
B20: =IF($A20="","",Config!$G$5) | D20: =IF($A20="","",COUNTIFS('My Books'!$E$5:$E$24,$A20,'My Books'!$F$5:$F$24,"Published")) | E20: =IF($A20="","",COUNTIFS('My Books'!$E$5:$E$24,$A20,'My Books'!$F$5:$F$24,"<>Published",'My Books'!$B$5:$B$24,"<>")) | F20: =IF($A20="","",SUMIF('My Books'!$E$5:$E$24,$A20,'My Books'!$H$5:$H$24)) | H20: =IF($A20="","",IF(OR($C20="",$C20<=0),"⚠ Set planned count",IF(COUNTIF('My Books'!$E$5:$E$24,$A20)=0,"⚠ No books cataloged",IF(COUNTIF('My Books'!$E$5:$E$24,$A20)=$C20,"✓ All "&$C20&" planned books cataloged",IF(COUNTIF('My Books'!$E$5:$E$24,$A20)<$C20,"✓ "&COUNTIF('My Books'!$E$5:$E$24,$A20)&" of "&$C20&" cataloged ("&($C20-COUNTIF('My Books'!$E$5:$E$24,$A20))&" future)","⚠ More cataloged than planned"))))) | I20: =IF($A20="","",IF(SUMIF('My Books'!$E$5:$E$24,$A20,'My Books'!$G$5:$G$24)>0,SUMIF('My Books'!$E$5:$E$24,$A20,'My Books'!$Q$5:$Q$24)/SUMIF('My Books'!$E$5:$E$24,$A20,'My Books'!$G$5:$G$24),0))
B21: =IF($A21="","",Config!$G$5) | D21: =IF($A21="","",COUNTIFS('My Books'!$E$5:$E$24,$A21,'My Books'!$F$5:$F$24,"Published")) | E21: =IF($A21="","",COUNTIFS('My Books'!$E$5:$E$24,$A21,'My Books'!$F$5:$F$24,"<>Published",'My Books'!$B$5:$B$24,"<>")) | F21: =IF($A21="","",SUMIF('My Books'!$E$5:$E$24,$A21,'My Books'!$H$5:$H$24)) | H21: =IF($A21="","",IF(OR($C21="",$C21<=0),"⚠ Set planned count",IF(COUNTIF('My Books'!$E$5:$E$24,$A21)=0,"⚠ No books cataloged",IF(COUNTIF('My Books'!$E$5:$E$24,$A21)=$C21,"✓ All "&$C21&" planned books cataloged",IF(COUNTIF('My Books'!$E$5:$E$24,$A21)<$C21,"✓ "&COUNTIF('My Books'!$E$5:$E$24,$A21)&" of "&$C21&" cataloged ("&($C21-COUNTIF('My Books'!$E$5:$E$24,$A21))&" future)","⚠ More cataloged than planned"))))) | I21: =IF($A21="","",IF(SUMIF('My Books'!$E$5:$E$24,$A21,'My Books'!$G$5:$G$24)>0,SUMIF('My Books'!$E$5:$E$24,$A21,'My Books'!$Q$5:$Q$24)/SUMIF('My Books'!$E$5:$E$24,$A21,'My Books'!$G$5:$G$24),0))
B22: =IF($A22="","",Config!$G$5) | D22: =IF($A22="","",COUNTIFS('My Books'!$E$5:$E$24,$A22,'My Books'!$F$5:$F$24,"Published")) | E22: =IF($A22="","",COUNTIFS('My Books'!$E$5:$E$24,$A22,'My Books'!$F$5:$F$24,"<>Published",'My Books'!$B$5:$B$24,"<>")) | F22: =IF($A22="","",SUMIF('My Books'!$E$5:$E$24,$A22,'My Books'!$H$5:$H$24)) | H22: =IF($A22="","",IF(OR($C22="",$C22<=0),"⚠ Set planned count",IF(COUNTIF('My Books'!$E$5:$E$24,$A22)=0,"⚠ No books cataloged",IF(COUNTIF('My Books'!$E$5:$E$24,$A22)=$C22,"✓ All "&$C22&" planned books cataloged",IF(COUNTIF('My Books'!$E$5:$E$24,$A22)<$C22,"✓ "&COUNTIF('My Books'!$E$5:$E$24,$A22)&" of "&$C22&" cataloged ("&($C22-COUNTIF('My Books'!$E$5:$E$24,$A22))&" future)","⚠ More cataloged than planned"))))) | I22: =IF($A22="","",IF(SUMIF('My Books'!$E$5:$E$24,$A22,'My Books'!$G$5:$G$24)>0,SUMIF('My Books'!$E$5:$E$24,$A22,'My Books'!$Q$5:$Q$24)/SUMIF('My Books'!$E$5:$E$24,$A22,'My Books'!$G$5:$G$24),0))
... B24: =IF($A24="","",Config!$G$5) | D24: =IF($A24="","",COUNTIFS('My Books'!$E$5:$E$24,$A24,'My Books'!$F$5:$F$24,"Published")) | E24: =IF($A24="","",COUNTIFS('My Books'!$E$5:$E$24,$A24,'My Books'!$F$5:$F$24,"<>Published",'My Books'!$B$5:$B$24,"<>")) | F24: =IF($A24="","",SUMIF('My Books'!$E$5:$E$24,$A24,'My Books'!$H$5:$H$24)) | H24: =IF($A24="","",IF(OR($C24="",$C24<=0),"⚠ Set planned count",IF(COUNTIF('My Books'!$E$5:$E$24,$A24)=0,"⚠ No books cataloged",IF(COUNTIF('My Books'!$E$5:$E$24,$A24)=$C24,"✓ All "&$C24&" planned books cataloged",IF(COUNTIF('My Books'!$E$5:$E$24,$A24)<$C24,"✓ "&COUNTIF('My Books'!$E$5:$E$24,$A24)&" of "&$C24&" cataloged ("&($C24-COUNTIF('My Books'!$E$5:$E$24,$A24))&" future)","⚠ More cataloged than planned"))))) | I24: =IF($A24="","",IF(SUMIF('My Books'!$E$5:$E$24,$A24,'My Books'!$G$5:$G$24)>0,SUMIF('My Books'!$E$5:$E$24,$A24,'My Books'!$Q$5:$Q$24)/SUMIF('My Books'!$E$5:$E$24,$A24,'My Books'!$G$5:$G$24),0))
A25: Total Canon Portfolio | C25: =SUM(C5:C24) -> 24 | D25: =SUM(D5:D24) -> 0 | E25: =SUM(E5:E24) -> 6 | F25: =SUM(F5:F24) -> 7450 | H25: =IF(COUNTIF(H5:H24,"⚠*")=0,"✓ All Series Aligned ("&E25&" of "&C25&" Cataloged)","⚠ Check Mismatches") -> ✓ All Series Aligned (6 of 24 Cataloged) | I25: =IF(COUNT(I5:I24)>0,AVERAGE(I5:I24),0) -> 0.0079166667
A27: 📊 SERIES CANON ARCHITECTURE & WORD VOLUME ANALYTICS (AUTO-UPDATES AS SERIES & BOOKS ARE ADDED)

Sheet My Books
A1: 📖 MY BOOKS • MULTI-YEAR PROJECT PIPELINE
A2: Total Work Words includes worldbuilding, outlining, first-draft and revision output. Draft target progress, required pace, status and forecast use First Draft Words only; revision words are not counted a second time. Check final manuscript length in the manuscript file.
A4: Year | B4: Book Title | C4: Type | D4: Universe | E4: Series | F4: Current Stage | G4: Draft Target Words | H4: Total Work Words | I4: Draft Progress % | J4: Draft Progress Bar | K4: Start Date | L4: Deadline | M4: Days Left | N4: Required Draft Words/Day | O4: Recent Draft Speed (30D) | P4: Forecasted Draft Target | Q4: Draft Words | R4: Status
A5: 2027 | B5: Prisoner of Sand Sea | C5: Novel | D5: =IF(B5="","",IF(E5="","Standalone",IFERROR(INDEX('Universes & Series'!$B$5:$B$24,MATCH(E5,'Universes & Series'!$A$5:$A$24,0)),"Unknown Series"))) -> Reliquary | E5: Sand Sea Saga | F5: Concept | G5: 200000 | H5: =IF(B5="","",SUMIFS('Daily Writing Log'!$H$5:$H$34,'Daily Writing Log'!$B$5:$B$34,B5)) -> 0 | I5: =IF(B5="","",IF(G5>0,MIN(1,Q5/G5),0)) -> 0 | J5: =IF(B5="","",REPT("█",ROUND(I5*20,0))&REPT("-",20-ROUND(I5*20,0))) -> -------------------- | K5: 46388 | L5: 46569 | M5: =IF($B5="","",IF($L5="","",MAX(0,$L5-Config!$A$2))) -> 257 | N5: =IF($B5="","",IF(OR($G5<=0,$Q5>=$G5),0,IF(OR($L5="",NOT(ISNUMBER($L5))),0,ROUNDUP(MAX(0,$G5-$Q5)/MAX(1,$L5-MAX(Config!$A$2,N($K5))),0)))) -> 1105 | O5: =IF($B5="","",ROUND(SUMIFS('Daily Writing Log'!$F$5:$F$34,'Daily Writing Log'!$B$5:$B$34,$B5,'Daily Writing Log'!$A$5:$A$34,">="&(Config!$A$2-29),'Daily Writing Log'!$A$5:$A$34,"<="&Config!$A$2)/30,0)) -> 0 | P5: =IF($B5="","",IF($G5<=0,"Add target",IF($Q5>=$G5,"Completed",IF($O5>0,Config!$A$2+ROUNDUP(MAX(0,$G5-$Q5)/$O5,0),"No recent pace")))) -> No recent pace | Q5: =IF(B5="","",SUMIFS('Daily Writing Log'!$F$5:$F$34,'Daily Writing Log'!$B$5:$B$34,B5)) -> 0 | R5: =IF(B5="","",IF(F5="Published","✅ Published",IF(I5>=1,"🎉 Draft Complete",IF(M5<0,"🔴 Overdue",IF(Q5>0,"🟢 In Progress",IF(H5>0,"🔵 Outlining / Lore","⚪ Not Started")))))) -> ⚪ Not Started
A6: 2027 | B6: Gothic Fantasy 1 | C6: Novel | D6: =IF(B6="","",IF(E6="","Standalone",IFERROR(INDEX('Universes & Series'!$B$5:$B$24,MATCH(E6,'Universes & Series'!$A$5:$A$24,0)),"Unknown Series"))) -> Reliquary | E6: Gothic Fantasy Series | F6: Concept | G6: 150000 | H6: =IF(B6="","",SUMIFS('Daily Writing Log'!$H$5:$H$34,'Daily Writing Log'!$B$5:$B$34,B6)) -> 0 | I6: =IF(B6="","",IF(G6>0,MIN(1,Q6/G6),0)) -> 0 | J6: =IF(B6="","",REPT("█",ROUND(I6*20,0))&REPT("-",20-ROUND(I6*20,0))) -> -------------------- | K6: 46569 | L6: 46753 | M6: =IF($B6="","",IF($L6="","",MAX(0,$L6-Config!$A$2))) -> 441 | N6: =IF($B6="","",IF(OR($G6<=0,$Q6>=$G6),0,IF(OR($L6="",NOT(ISNUMBER($L6))),0,ROUNDUP(MAX(0,$G6-$Q6)/MAX(1,$L6-MAX(Config!$A$2,N($K6))),0)))) -> 816 | O6: =IF($B6="","",ROUND(SUMIFS('Daily Writing Log'!$F$5:$F$34,'Daily Writing Log'!$B$5:$B$34,$B6,'Daily Writing Log'!$A$5:$A$34,">="&(Config!$A$2-29),'Daily Writing Log'!$A$5:$A$34,"<="&Config!$A$2)/30,0)) -> 0 | P6: =IF($B6="","",IF($G6<=0,"Add target",IF($Q6>=$G6,"Completed",IF($O6>0,Config!$A$2+ROUNDUP(MAX(0,$G6-$Q6)/$O6,0),"No recent pace")))) -> No recent pace | Q6: =IF(B6="","",SUMIFS('Daily Writing Log'!$F$5:$F$34,'Daily Writing Log'!$B$5:$B$34,B6)) -> 0 | R6: =IF(B6="","",IF(F6="Published","✅ Published",IF(I6>=1,"🎉 Draft Complete",IF(M6<0,"🔴 Overdue",IF(Q6>0,"🟢 In Progress",IF(H6>0,"🔵 Outlining / Lore","⚪ Not Started")))))) -> ⚪ Not Started
A7: 2028 | B7: Quest Fantasy 1 | C7: Novel | D7: =IF(B7="","",IF(E7="","Standalone",IFERROR(INDEX('Universes & Series'!$B$5:$B$24,MATCH(E7,'Universes & Series'!$A$5:$A$24,0)),"Unknown Series"))) -> Reliquary | E7: Classic Quest Fantasy | F7: Concept | G7: 200000 | H7: =IF(B7="","",SUMIFS('Daily Writing Log'!$H$5:$H$34,'Daily Writing Log'!$B$5:$B$34,B7)) -> 0 | I7: =IF(B7="","",IF(G7>0,MIN(1,Q7/G7),0)) -> 0 | J7: =IF(B7="","",REPT("█",ROUND(I7*20,0))&REPT("-",20-ROUND(I7*20,0))) -> -------------------- | K7: 46753 | L7: 46874 | M7: =IF($B7="","",IF($L7="","",MAX(0,$L7-Config!$A$2))) -> 562 | N7: =IF($B7="","",IF(OR($G7<=0,$Q7>=$G7),0,IF(OR($L7="",NOT(ISNUMBER($L7))),0,ROUNDUP(MAX(0,$G7-$Q7)/MAX(1,$L7-MAX(Config!$A$2,N($K7))),0)))) -> 1653 | O7: =IF($B7="","",ROUND(SUMIFS('Daily Writing Log'!$F$5:$F$34,'Daily Writing Log'!$B$5:$B$34,$B7,'Daily Writing Log'!$A$5:$A$34,">="&(Config!$A$2-29),'Daily Writing Log'!$A$5:$A$34,"<="&Config!$A$2)/30,0)) -> 0 | P7: =IF($B7="","",IF($G7<=0,"Add target",IF($Q7>=$G7,"Completed",IF($O7>0,Config!$A$2+ROUNDUP(MAX(0,$G7-$Q7)/$O7,0),"No recent pace")))) -> No recent pace | Q7: =IF(B7="","",SUMIFS('Daily Writing Log'!$F$5:$F$34,'Daily Writing Log'!$B$5:$B$34,B7)) -> 0 | R7: =IF(B7="","",IF(F7="Published","✅ Published",IF(I7>=1,"🎉 Draft Complete",IF(M7<0,"🔴 Overdue",IF(Q7>0,"🟢 In Progress",IF(H7>0,"🔵 Outlining / Lore","⚪ Not Started")))))) -> ⚪ Not Started
A8: 2028 | B8: Ruler of Sand Sea | C8: Novel | D8: =IF(B8="","",IF(E8="","Standalone",IFERROR(INDEX('Universes & Series'!$B$5:$B$24,MATCH(E8,'Universes & Series'!$A$5:$A$24,0)),"Unknown Series"))) -> Reliquary | E8: Sand Sea Saga | F8: Concept | G8: 200000 | H8: =IF(B8="","",SUMIFS('Daily Writing Log'!$H$5:$H$34,'Daily Writing Log'!$B$5:$B$34,B8)) -> 0 | I8: =IF(B8="","",IF(G8>0,MIN(1,Q8/G8),0)) -> 0 | J8: =IF(B8="","",REPT("█",ROUND(I8*20,0))&REPT("-",20-ROUND(I8*20,0))) -> -------------------- | K8: 46874 | L8: 46997 | M8: =IF($B8="","",IF($L8="","",MAX(0,$L8-Config!$A$2))) -> 685 | N8: =IF($B8="","",IF(OR($G8<=0,$Q8>=$G8),0,IF(OR($L8="",NOT(ISNUMBER($L8))),0,ROUNDUP(MAX(0,$G8-$Q8)/MAX(1,$L8-MAX(Config!$A$2,N($K8))),0)))) -> 1627 | O8: =IF($B8="","",ROUND(SUMIFS('Daily Writing Log'!$F$5:$F$34,'Daily Writing Log'!$B$5:$B$34,$B8,'Daily Writing Log'!$A$5:$A$34,">="&(Config!$A$2-29),'Daily Writing Log'!$A$5:$A$34,"<="&Config!$A$2)/30,0)) -> 0 | P8: =IF($B8="","",IF($G8<=0,"Add target",IF($Q8>=$G8,"Completed",IF($O8>0,Config!$A$2+ROUNDUP(MAX(0,$G8-$Q8)/$O8,0),"No recent pace")))) -> No recent pace | Q8: =IF(B8="","",SUMIFS('Daily Writing Log'!$F$5:$F$34,'Daily Writing Log'!$B$5:$B$34,B8)) -> 0 | R8: =IF(B8="","",IF(F8="Published","✅ Published",IF(I8>=1,"🎉 Draft Complete",IF(M8<0,"🔴 Overdue",IF(Q8>0,"🟢 In Progress",IF(H8>0,"🔵 Outlining / Lore","⚪ Not Started")))))) -> ⚪ Not Started
A9: 2028 | B9: Company of the Storm | C9: Novel | D9: =IF(B9="","",IF(E9="","Standalone",IFERROR(INDEX('Universes & Series'!$B$5:$B$24,MATCH(E9,'Universes & Series'!$A$5:$A$24,0)),"Unknown Series"))) -> Reliquary | E9: Stormbreaker Chronicles | F9: Concept | G9: 150000 | H9: =IF(B9="","",SUMIFS('Daily Writing Log'!$H$5:$H$34,'Daily Writing Log'!$B$5:$B$34,B9)) -> 0 | I9: =IF(B9="","",IF(G9>0,MIN(1,Q9/G9),0)) -> 0 | J9: =IF(B9="","",REPT("█",ROUND(I9*20,0))&REPT("-",20-ROUND(I9*20,0))) -> -------------------- | K9: 46997 | L9: 47119 | M9: =IF($B9="","",IF($L9="","",MAX(0,$L9-Config!$A$2))) -> 807 | N9: =IF($B9="","",IF(OR($G9<=0,$Q9>=$G9),0,IF(OR($L9="",NOT(ISNUMBER($L9))),0,ROUNDUP(MAX(0,$G9-$Q9)/MAX(1,$L9-MAX(Config!$A$2,N($K9))),0)))) -> 1230 | O9: =IF($B9="","",ROUND(SUMIFS('Daily Writing Log'!$F$5:$F$34,'Daily Writing Log'!$B$5:$B$34,$B9,'Daily Writing Log'!$A$5:$A$34,">="&(Config!$A$2-29),'Daily Writing Log'!$A$5:$A$34,"<="&Config!$A$2)/30,0)) -> 0 | P9: =IF($B9="","",IF($G9<=0,"Add target",IF($Q9>=$G9,"Completed",IF($O9>0,Config!$A$2+ROUNDUP(MAX(0,$G9-$Q9)/$O9,0),"No recent pace")))) -> No recent pace | Q9: =IF(B9="","",SUMIFS('Daily Writing Log'!$F$5:$F$34,'Daily Writing Log'!$B$5:$B$34,B9)) -> 0 | R9: =IF(B9="","",IF(F9="Published","✅ Published",IF(I9>=1,"🎉 Draft Complete",IF(M9<0,"🔴 Overdue",IF(Q9>0,"🟢 In Progress",IF(H9>0,"🔵 Outlining / Lore","⚪ Not Started")))))) -> ⚪ Not Started
A10: 2026 | B10: The Silver Chronicles | C10: Novel | D10: =IF(B10="","",IF(E10="","Standalone",IFERROR(INDEX('Universes & Series'!$B$5:$B$24,MATCH(E10,'Universes & Series'!$A$5:$A$24,0)),"Unknown Series"))) -> Eldoria-Cosmos | E10: The Silver Chronicles | F10: Drafting | G10: 120000 | H10: =IF(B10="","",SUMIFS('Daily Writing Log'!$H$5:$H$34,'Daily Writing Log'!$B$5:$B$34,B10)) -> 7450 | I10: =IF(B10="","",IF(G10>0,MIN(1,Q10/G10),0)) -> 0.0475 | J10: =IF(B10="","",REPT("█",ROUND(I10*20,0))&REPT("-",20-ROUND(I10*20,0))) -> █------------------- | K10: 2026-10-01 | L10: 2027-06-01 | M10: =IF($B10="","",IF($L10="","",MAX(0,$L10-Config!$A$2))) -> 227 | N10: =IF($B10="","",IF(OR($G10<=0,$Q10>=$G10),0,IF(OR($L10="",NOT(ISNUMBER($L10))),0,ROUNDUP(MAX(0,$G10-$Q10)/MAX(1,$L10-MAX(Config!$A$2,N($K10))),0)))) -> 0 | O10: =IF($B10="","",ROUND(SUMIFS('Daily Writing Log'!$F$5:$F$34,'Daily Writing Log'!$B$5:$B$34,$B10,'Daily Writing Log'!$A$5:$A$34,">="&(Config!$A$2-29),'Daily Writing Log'!$A$5:$A$34,"<="&Config!$A$2)/30,0)) -> 0 | P10: =IF($B10="","",IF($G10<=0,"Add target",IF($Q10>=$G10,"Completed",IF($O10>0,Config!$A$2+ROUNDUP(MAX(0,$G10-$Q10)/$O10,0),"No recent pace")))) -> No recent pace | Q10: =IF(B10="","",SUMIFS('Daily Writing Log'!$F$5:$F$34,'Daily Writing Log'!$B$5:$B$34,B10)) -> 5700 | R10: =IF(B10="","",IF(F10="Published","✅ Published",IF(I10>=1,"🎉 Draft Complete",IF(M10<0,"🔴 Overdue",IF(Q10>0,"🟢 In Progress",IF(H10>0,"🔵 Outlining / Lore","⚪ Not Started")))))) -> 🟢 In Progress
A11: =IF($B11="","",IF(ISNUMBER($K11),YEAR($K11),IF(ISNUMBER($L11),YEAR($L11),YEAR(Config!$A$2)))) | C11: =IF($B11="","",Config!$E$5) | D11: =IF($B11="","",IF($E11="","Standalone",IF(COUNTIF('Universes & Series'!$A$5:$A$24,$E11)>0,INDEX('Universes & Series'!$B$5:$B$24,MATCH($E11,'Universes & Series'!$A$5:$A$24,0)),Config!$G$5))) | F11: =IF($B11="","",Config!$F$5) | H11: =IF($B11="","",SUMIFS('Daily Writing Log'!$H$5:$H$34,'Daily Writing Log'!$B$5:$B$34,$B11)) | I11: =IF($B11="","",IF($G11>0,MIN(1,MAX(0,$Q11/$G11)),0)) | J11: =IF($B11="","",REPT("#",IF($I11>0,MAX(1,ROUNDUP(MIN(1,MAX(0,$I11))*20,0)),0))&REPT("-",20-IF($I11>0,MAX(1,ROUNDUP(MIN(1,MAX(0,$I11))*20,0)),0))) | M11: =IF($B11="","",IF($L11="","",MAX(0,$L11-Config!$A$2))) | N11: =IF($B11="","",IF(OR($G11<=0,$Q11>=$G11),0,IF(OR($L11="",NOT(ISNUMBER($L11))),0,ROUNDUP(MAX(0,$G11-$Q11)/MAX(1,$L11-MAX(Config!$A$2,N($K11))),0)))) | O11: =IF($B11="","",ROUND(SUMIFS('Daily Writing Log'!$F$5:$F$34,'Daily Writing Log'!$B$5:$B$34,$B11,'Daily Writing Log'!$A$5:$A$34,">="&(Config!$A$2-29),'Daily Writing Log'!$A$5:$A$34,"<="&Config!$A$2)/30,0)) | P11: =IF($B11="","",IF($G11<=0,"Add target",IF($Q11>=$G11,"Completed",IF($O11>0,Config!$A$2+ROUNDUP(MAX(0,$G11-$Q11)/$O11,0),"No recent pace")))) | Q11: =IF($B11="","",SUMIFS('Daily Writing Log'!$F$5:$F$34,'Daily Writing Log'!$B$5:$B$34,$B11)) | R11: =IF($B11="","",IF($F11="Published","🎉 Published",IF($G11<=0,"⚪ Set target",IF($Q11>=$G11,"✅ Draft Target Met",IF(AND(ISNUMBER($K11),$K11>Config!$A$2),"⚪ Not Started",IF($F11="Concept","🔵 In Concept",IF(ISBLANK($L11),"In Progress",IF(Config!$A$2>$L11,"🔴 Overdue",IF($O11>=$N11,"🟢 On Track",IF($O11>=$N11*0.6,"🟡 Needs Focus","🔴 Behind Schedule"))))))))))
A12: =IF($B12="","",IF(ISNUMBER($K12),YEAR($K12),IF(ISNUMBER($L12),YEAR($L12),YEAR(Config!$A$2)))) | C12: =IF($B12="","",Config!$E$5) | D12: =IF($B12="","",IF($E12="","Standalone",IF(COUNTIF('Universes & Series'!$A$5:$A$24,$E12)>0,INDEX('Universes & Series'!$B$5:$B$24,MATCH($E12,'Universes & Series'!$A$5:$A$24,0)),Config!$G$5))) | F12: =IF($B12="","",Config!$F$5) | H12: =IF($B12="","",SUMIFS('Daily Writing Log'!$H$5:$H$34,'Daily Writing Log'!$B$5:$B$34,$B12)) | I12: =IF($B12="","",IF($G12>0,MIN(1,MAX(0,$Q12/$G12)),0)) | J12: =IF($B12="","",REPT("#",IF($I12>0,MAX(1,ROUNDUP(MIN(1,MAX(0,$I12))*20,0)),0))&REPT("-",20-IF($I12>0,MAX(1,ROUNDUP(MIN(1,MAX(0,$I12))*20,0)),0))) | M12: =IF($B12="","",IF($L12="","",MAX(0,$L12-Config!$A$2))) | N12: =IF($B12="","",IF(OR($G12<=0,$Q12>=$G12),0,IF(OR($L12="",NOT(ISNUMBER($L12))),0,ROUNDUP(MAX(0,$G12-$Q12)/MAX(1,$L12-MAX(Config!$A$2,N($K12))),0)))) | O12: =IF($B12="","",ROUND(SUMIFS('Daily Writing Log'!$F$5:$F$34,'Daily Writing Log'!$B$5:$B$34,$B12,'Daily Writing Log'!$A$5:$A$34,">="&(Config!$A$2-29),'Daily Writing Log'!$A$5:$A$34,"<="&Config!$A$2)/30,0)) | P12: =IF($B12="","",IF($G12<=0,"Add target",IF($Q12>=$G12,"Completed",IF($O12>0,Config!$A$2+ROUNDUP(MAX(0,$G12-$Q12)/$O12,0),"No recent pace")))) | Q12: =IF($B12="","",SUMIFS('Daily Writing Log'!$F$5:$F$34,'Daily Writing Log'!$B$5:$B$34,$B12)) | R12: =IF($B12="","",IF($F12="Published","🎉 Published",IF($G12<=0,"⚪ Set target",IF($Q12>=$G12,"✅ Draft Target Met",IF(AND(ISNUMBER($K12),$K12>Config!$A$2),"⚪ Not Started",IF($F12="Concept","🔵 In Concept",IF(ISBLANK($L12),"In Progress",IF(Config!$A$2>$L12,"🔴 Overdue",IF($O12>=$N12,"🟢 On Track",IF($O12>=$N12*0.6,"🟡 Needs Focus","🔴 Behind Schedule"))))))))))
A13: =IF($B13="","",IF(ISNUMBER($K13),YEAR($K13),IF(ISNUMBER($L13),YEAR($L13),YEAR(Config!$A$2)))) | C13: =IF($B13="","",Config!$E$5) | D13: =IF($B13="","",IF($E13="","Standalone",IF(COUNTIF('Universes & Series'!$A$5:$A$24,$E13)>0,INDEX('Universes & Series'!$B$5:$B$24,MATCH($E13,'Universes & Series'!$A$5:$A$24,0)),Config!$G$5))) | F13: =IF($B13="","",Config!$F$5) | H13: =IF($B13="","",SUMIFS('Daily Writing Log'!$H$5:$H$34,'Daily Writing Log'!$B$5:$B$34,$B13)) | I13: =IF($B13="","",IF($G13>0,MIN(1,MAX(0,$Q13/$G13)),0)) | J13: =IF($B13="","",REPT("#",IF($I13>0,MAX(1,ROUNDUP(MIN(1,MAX(0,$I13))*20,0)),0))&REPT("-",20-IF($I13>0,MAX(1,ROUNDUP(MIN(1,MAX(0,$I13))*20,0)),0))) | M13: =IF($B13="","",IF($L13="","",MAX(0,$L13-Config!$A$2))) | N13: =IF($B13="","",IF(OR($G13<=0,$Q13>=$G13),0,IF(OR($L13="",NOT(ISNUMBER($L13))),0,ROUNDUP(MAX(0,$G13-$Q13)/MAX(1,$L13-MAX(Config!$A$2,N($K13))),0)))) | O13: =IF($B13="","",ROUND(SUMIFS('Daily Writing Log'!$F$5:$F$34,'Daily Writing Log'!$B$5:$B$34,$B13,'Daily Writing Log'!$A$5:$A$34,">="&(Config!$A$2-29),'Daily Writing Log'!$A$5:$A$34,"<="&Config!$A$2)/30,0)) | P13: =IF($B13="","",IF($G13<=0,"Add target",IF($Q13>=$G13,"Completed",IF($O13>0,Config!$A$2+ROUNDUP(MAX(0,$G13-$Q13)/$O13,0),"No recent pace")))) | Q13: =IF($B13="","",SUMIFS('Daily Writing Log'!$F$5:$F$34,'Daily Writing Log'!$B$5:$B$34,$B13)) | R13: =IF($B13="","",IF($F13="Published","🎉 Published",IF($G13<=0,"⚪ Set target",IF($Q13>=$G13,"✅ Draft Target Met",IF(AND(ISNUMBER($K13),$K13>Config!$A$2),"⚪ Not Started",IF($F13="Concept","🔵 In Concept",IF(ISBLANK($L13),"In Progress",IF(Config!$A$2>$L13,"🔴 Overdue",IF($O13>=$N13,"🟢 On Track",IF($O13>=$N13*0.6,"🟡 Needs Focus","🔴 Behind Schedule"))))))))))
A14: =IF($B14="","",IF(ISNUMBER($K14),YEAR($K14),IF(ISNUMBER($L14),YEAR($L14),YEAR(Config!$A$2)))) | C14: =IF($B14="","",Config!$E$5) | D14: =IF($B14="","",IF($E14="","Standalone",IF(COUNTIF('Universes & Series'!$A$5:$A$24,$E14)>0,INDEX('Universes & Series'!$B$5:$B$24,MATCH($E14,'Universes & Series'!$A$5:$A$24,0)),Config!$G$5))) | F14: =IF($B14="","",Config!$F$5) | H14: =IF($B14="","",SUMIFS('Daily Writing Log'!$H$5:$H$34,'Daily Writing Log'!$B$5:$B$34,$B14)) | I14: =IF($B14="","",IF($G14>0,MIN(1,MAX(0,$Q14/$G14)),0)) | J14: =IF($B14="","",REPT("#",IF($I14>0,MAX(1,ROUNDUP(MIN(1,MAX(0,$I14))*20,0)),0))&REPT("-",20-IF($I14>0,MAX(1,ROUNDUP(MIN(1,MAX(0,$I14))*20,0)),0))) | M14: =IF($B14="","",IF($L14="","",MAX(0,$L14-Config!$A$2))) | N14: =IF($B14="","",IF(OR($G14<=0,$Q14>=$G14),0,IF(OR($L14="",NOT(ISNUMBER($L14))),0,ROUNDUP(MAX(0,$G14-$Q14)/MAX(1,$L14-MAX(Config!$A$2,N($K14))),0)))) | O14: =IF($B14="","",ROUND(SUMIFS('Daily Writing Log'!$F$5:$F$34,'Daily Writing Log'!$B$5:$B$34,$B14,'Daily Writing Log'!$A$5:$A$34,">="&(Config!$A$2-29),'Daily Writing Log'!$A$5:$A$34,"<="&Config!$A$2)/30,0)) | P14: =IF($B14="","",IF($G14<=0,"Add target",IF($Q14>=$G14,"Completed",IF($O14>0,Config!$A$2+ROUNDUP(MAX(0,$G14-$Q14)/$O14,0),"No recent pace")))) | Q14: =IF($B14="","",SUMIFS('Daily Writing Log'!$F$5:$F$34,'Daily Writing Log'!$B$5:$B$34,$B14)) | R14: =IF($B14="","",IF($F14="Published","🎉 Published",IF($G14<=0,"⚪ Set target",IF($Q14>=$G14,"✅ Draft Target Met",IF(AND(ISNUMBER($K14),$K14>Config!$A$2),"⚪ Not Started",IF($F14="Concept","🔵 In Concept",IF(ISBLANK($L14),"In Progress",IF(Config!$A$2>$L14,"🔴 Overdue",IF($O14>=$N14,"🟢 On Track",IF($O14>=$N14*0.6,"🟡 Needs Focus","🔴 Behind Schedule"))))))))))
A15: =IF($B15="","",IF(ISNUMBER($K15),YEAR($K15),IF(ISNUMBER($L15),YEAR($L15),YEAR(Config!$A$2)))) | C15: =IF($B15="","",Config!$E$5) | D15: =IF($B15="","",IF($E15="","Standalone",IF(COUNTIF('Universes & Series'!$A$5:$A$24,$E15)>0,INDEX('Universes & Series'!$B$5:$B$24,MATCH($E15,'Universes & Series'!$A$5:$A$24,0)),Config!$G$5))) | F15: =IF($B15="","",Config!$F$5) | H15: =IF($B15="","",SUMIFS('Daily Writing Log'!$H$5:$H$34,'Daily Writing Log'!$B$5:$B$34,$B15)) | I15: =IF($B15="","",IF($G15>0,MIN(1,MAX(0,$Q15/$G15)),0)) | J15: =IF($B15="","",REPT("#",IF($I15>0,MAX(1,ROUNDUP(MIN(1,MAX(0,$I15))*20,0)),0))&REPT("-",20-IF($I15>0,MAX(1,ROUNDUP(MIN(1,MAX(0,$I15))*20,0)),0))) | M15: =IF($B15="","",IF($L15="","",MAX(0,$L15-Config!$A$2))) | N15: =IF($B15="","",IF(OR($G15<=0,$Q15>=$G15),0,IF(OR($L15="",NOT(ISNUMBER($L15))),0,ROUNDUP(MAX(0,$G15-$Q15)/MAX(1,$L15-MAX(Config!$A$2,N($K15))),0)))) | O15: =IF($B15="","",ROUND(SUMIFS('Daily Writing Log'!$F$5:$F$34,'Daily Writing Log'!$B$5:$B$34,$B15,'Daily Writing Log'!$A$5:$A$34,">="&(Config!$A$2-29),'Daily Writing Log'!$A$5:$A$34,"<="&Config!$A$2)/30,0)) | P15: =IF($B15="","",IF($G15<=0,"Add target",IF($Q15>=$G15,"Completed",IF($O15>0,Config!$A$2+ROUNDUP(MAX(0,$G15-$Q15)/$O15,0),"No recent pace")))) | Q15: =IF($B15="","",SUMIFS('Daily Writing Log'!$F$5:$F$34,'Daily Writing Log'!$B$5:$B$34,$B15)) | R15: =IF($B15="","",IF($F15="Published","🎉 Published",IF($G15<=0,"⚪ Set target",IF($Q15>=$G15,"✅ Draft Target Met",IF(AND(ISNUMBER($K15),$K15>Config!$A$2),"⚪ Not Started",IF($F15="Concept","🔵 In Concept",IF(ISBLANK($L15),"In Progress",IF(Config!$A$2>$L15,"🔴 Overdue",IF($O15>=$N15,"🟢 On Track",IF($O15>=$N15*0.6,"🟡 Needs Focus","🔴 Behind Schedule"))))))))))
A16: =IF($B16="","",IF(ISNUMBER($K16),YEAR($K16),IF(ISNUMBER($L16),YEAR($L16),YEAR(Config!$A$2)))) | C16: =IF($B16="","",Config!$E$5) | D16: =IF($B16="","",IF($E16="","Standalone",IF(COUNTIF('Universes & Series'!$A$5:$A$24,$E16)>0,INDEX('Universes & Series'!$B$5:$B$24,MATCH($E16,'Universes & Series'!$A$5:$A$24,0)),Config!$G$5))) | F16: =IF($B16="","",Config!$F$5) | H16: =IF($B16="","",SUMIFS('Daily Writing Log'!$H$5:$H$34,'Daily Writing Log'!$B$5:$B$34,$B16)) | I16: =IF($B16="","",IF($G16>0,MIN(1,MAX(0,$Q16/$G16)),0)) | J16: =IF($B16="","",REPT("#",IF($I16>0,MAX(1,ROUNDUP(MIN(1,MAX(0,$I16))*20,0)),0))&REPT("-",20-IF($I16>0,MAX(1,ROUNDUP(MIN(1,MAX(0,$I16))*20,0)),0))) | M16: =IF($B16="","",IF($L16="","",MAX(0,$L16-Config!$A$2))) | N16: =IF($B16="","",IF(OR($G16<=0,$Q16>=$G16),0,IF(OR($L16="",NOT(ISNUMBER($L16))),0,ROUNDUP(MAX(0,$G16-$Q16)/MAX(1,$L16-MAX(Config!$A$2,N($K16))),0)))) | O16: =IF($B16="","",ROUND(SUMIFS('Daily Writing Log'!$F$5:$F$34,'Daily Writing Log'!$B$5:$B$34,$B16,'Daily Writing Log'!$A$5:$A$34,">="&(Config!$A$2-29),'Daily Writing Log'!$A$5:$A$34,"<="&Config!$A$2)/30,0)) | P16: =IF($B16="","",IF($G16<=0,"Add target",IF($Q16>=$G16,"Completed",IF($O16>0,Config!$A$2+ROUNDUP(MAX(0,$G16-$Q16)/$O16,0),"No recent pace")))) | Q16: =IF($B16="","",SUMIFS('Daily Writing Log'!$F$5:$F$34,'Daily Writing Log'!$B$5:$B$34,$B16)) | R16: =IF($B16="","",IF($F16="Published","🎉 Published",IF($G16<=0,"⚪ Set target",IF($Q16>=$G16,"✅ Draft Target Met",IF(AND(ISNUMBER($K16),$K16>Config!$A$2),"⚪ Not Started",IF($F16="Concept","🔵 In Concept",IF(ISBLANK($L16),"In Progress",IF(Config!$A$2>$L16,"🔴 Overdue",IF($O16>=$N16,"🟢 On Track",IF($O16>=$N16*0.6,"🟡 Needs Focus","🔴 Behind Schedule"))))))))))
A17: =IF($B17="","",IF(ISNUMBER($K17),YEAR($K17),IF(ISNUMBER($L17),YEAR($L17),YEAR(Config!$A$2)))) | C17: =IF($B17="","",Config!$E$5) | D17: =IF($B17="","",IF($E17="","Standalone",IF(COUNTIF('Universes & Series'!$A$5:$A$24,$E17)>0,INDEX('Universes & Series'!$B$5:$B$24,MATCH($E17,'Universes & Series'!$A$5:$A$24,0)),Config!$G$5))) | F17: =IF($B17="","",Config!$F$5) | H17: =IF($B17="","",SUMIFS('Daily Writing Log'!$H$5:$H$34,'Daily Writing Log'!$B$5:$B$34,$B17)) | I17: =IF($B17="","",IF($G17>0,MIN(1,MAX(0,$Q17/$G17)),0)) | J17: =IF($B17="","",REPT("#",IF($I17>0,MAX(1,ROUNDUP(MIN(1,MAX(0,$I17))*20,0)),0))&REPT("-",20-IF($I17>0,MAX(1,ROUNDUP(MIN(1,MAX(0,$I17))*20,0)),0))) | M17: =IF($B17="","",IF($L17="","",MAX(0,$L17-Config!$A$2))) | N17: =IF($B17="","",IF(OR($G17<=0,$Q17>=$G17),0,IF(OR($L17="",NOT(ISNUMBER($L17))),0,ROUNDUP(MAX(0,$G17-$Q17)/MAX(1,$L17-MAX(Config!$A$2,N($K17))),0)))) | O17: =IF($B17="","",ROUND(SUMIFS('Daily Writing Log'!$F$5:$F$34,'Daily Writing Log'!$B$5:$B$34,$B17,'Daily Writing Log'!$A$5:$A$34,">="&(Config!$A$2-29),'Daily Writing Log'!$A$5:$A$34,"<="&Config!$A$2)/30,0)) | P17: =IF($B17="","",IF($G17<=0,"Add target",IF($Q17>=$G17,"Completed",IF($O17>0,Config!$A$2+ROUNDUP(MAX(0,$G17-$Q17)/$O17,0),"No recent pace")))) | Q17: =IF($B17="","",SUMIFS('Daily Writing Log'!$F$5:$F$34,'Daily Writing Log'!$B$5:$B$34,$B17)) | R17: =IF($B17="","",IF($F17="Published","🎉 Published",IF($G17<=0,"⚪ Set target",IF($Q17>=$G17,"✅ Draft Target Met",IF(AND(ISNUMBER($K17),$K17>Config!$A$2),"⚪ Not Started",IF($F17="Concept","🔵 In Concept",IF(ISBLANK($L17),"In Progress",IF(Config!$A$2>$L17,"🔴 Overdue",IF($O17>=$N17,"🟢 On Track",IF($O17>=$N17*0.6,"🟡 Needs Focus","🔴 Behind Schedule"))))))))))
A18: =IF($B18="","",IF(ISNUMBER($K18),YEAR($K18),IF(ISNUMBER($L18),YEAR($L18),YEAR(Config!$A$2)))) | C18: =IF($B18="","",Config!$E$5) | D18: =IF($B18="","",IF($E18="","Standalone",IF(COUNTIF('Universes & Series'!$A$5:$A$24,$E18)>0,INDEX('Universes & Series'!$B$5:$B$24,MATCH($E18,'Universes & Series'!$A$5:$A$24,0)),Config!$G$5))) | F18: =IF($B18="","",Config!$F$5) | H18: =IF($B18="","",SUMIFS('Daily Writing Log'!$H$5:$H$34,'Daily Writing Log'!$B$5:$B$34,$B18)) | I18: =IF($B18="","",IF($G18>0,MIN(1,MAX(0,$Q18/$G18)),0)) | J18: =IF($B18="","",REPT("#",IF($I18>0,MAX(1,ROUNDUP(MIN(1,MAX(0,$I18))*20,0)),0))&REPT("-",20-IF($I18>0,MAX(1,ROUNDUP(MIN(1,MAX(0,$I18))*20,0)),0))) | M18: =IF($B18="","",IF($L18="","",MAX(0,$L18-Config!$A$2))) | N18: =IF($B18="","",IF(OR($G18<=0,$Q18>=$G18),0,IF(OR($L18="",NOT(ISNUMBER($L18))),0,ROUNDUP(MAX(0,$G18-$Q18)/MAX(1,$L18-MAX(Config!$A$2,N($K18))),0)))) | O18: =IF($B18="","",ROUND(SUMIFS('Daily Writing Log'!$F$5:$F$34,'Daily Writing Log'!$B$5:$B$34,$B18,'Daily Writing Log'!$A$5:$A$34,">="&(Config!$A$2-29),'Daily Writing Log'!$A$5:$A$34,"<="&Config!$A$2)/30,0)) | P18: =IF($B18="","",IF($G18<=0,"Add target",IF($Q18>=$G18,"Completed",IF($O18>0,Config!$A$2+ROUNDUP(MAX(0,$G18-$Q18)/$O18,0),"No recent pace")))) | Q18: =IF($B18="","",SUMIFS('Daily Writing Log'!$F$5:$F$34,'Daily Writing Log'!$B$5:$B$34,$B18)) | R18: =IF($B18="","",IF($F18="Published","🎉 Published",IF($G18<=0,"⚪ Set target",IF($Q18>=$G18,"✅ Draft Target Met",IF(AND(ISNUMBER($K18),$K18>Config!$A$2),"⚪ Not Started",IF($F18="Concept","🔵 In Concept",IF(ISBLANK($L18),"In Progress",IF(Config!$A$2>$L18,"🔴 Overdue",IF($O18>=$N18,"🟢 On Track",IF($O18>=$N18*0.6,"🟡 Needs Focus","🔴 Behind Schedule"))))))))))
A19: =IF($B19="","",IF(ISNUMBER($K19),YEAR($K19),IF(ISNUMBER($L19),YEAR($L19),YEAR(Config!$A$2)))) | C19: =IF($B19="","",Config!$E$5) | D19: =IF($B19="","",IF($E19="","Standalone",IF(COUNTIF('Universes & Series'!$A$5:$A$24,$E19)>0,INDEX('Universes & Series'!$B$5:$B$24,MATCH($E19,'Universes & Series'!$A$5:$A$24,0)),Config!$G$5))) | F19: =IF($B19="","",Config!$F$5) | H19: =IF($B19="","",SUMIFS('Daily Writing Log'!$H$5:$H$34,'Daily Writing Log'!$B$5:$B$34,$B19)) | I19: =IF($B19="","",IF($G19>0,MIN(1,MAX(0,$Q19/$G19)),0)) | J19: =IF($B19="","",REPT("#",IF($I19>0,MAX(1,ROUNDUP(MIN(1,MAX(0,$I19))*20,0)),0))&REPT("-",20-IF($I19>0,MAX(1,ROUNDUP(MIN(1,MAX(0,$I19))*20,0)),0))) | M19: =IF($B19="","",IF($L19="","",MAX(0,$L19-Config!$A$2))) | N19: =IF($B19="","",IF(OR($G19<=0,$Q19>=$G19),0,IF(OR($L19="",NOT(ISNUMBER($L19))),0,ROUNDUP(MAX(0,$G19-$Q19)/MAX(1,$L19-MAX(Config!$A$2,N($K19))),0)))) | O19: =IF($B19="","",ROUND(SUMIFS('Daily Writing Log'!$F$5:$F$34,'Daily Writing Log'!$B$5:$B$34,$B19,'Daily Writing Log'!$A$5:$A$34,">="&(Config!$A$2-29),'Daily Writing Log'!$A$5:$A$34,"<="&Config!$A$2)/30,0)) | P19: =IF($B19="","",IF($G19<=0,"Add target",IF($Q19>=$G19,"Completed",IF($O19>0,Config!$A$2+ROUNDUP(MAX(0,$G19-$Q19)/$O19,0),"No recent pace")))) | Q19: =IF($B19="","",SUMIFS('Daily Writing Log'!$F$5:$F$34,'Daily Writing Log'!$B$5:$B$34,$B19)) | R19: =IF($B19="","",IF($F19="Published","🎉 Published",IF($G19<=0,"⚪ Set target",IF($Q19>=$G19,"✅ Draft Target Met",IF(AND(ISNUMBER($K19),$K19>Config!$A$2),"⚪ Not Started",IF($F19="Concept","🔵 In Concept",IF(ISBLANK($L19),"In Progress",IF(Config!$A$2>$L19,"🔴 Overdue",IF($O19>=$N19,"🟢 On Track",IF($O19>=$N19*0.6,"🟡 Needs Focus","🔴 Behind Schedule"))))))))))
A20: =IF($B20="","",IF(ISNUMBER($K20),YEAR($K20),IF(ISNUMBER($L20),YEAR($L20),YEAR(Config!$A$2)))) | C20: =IF($B20="","",Config!$E$5) | D20: =IF($B20="","",IF($E20="","Standalone",IF(COUNTIF('Universes & Series'!$A$5:$A$24,$E20)>0,INDEX('Universes & Series'!$B$5:$B$24,MATCH($E20,'Universes & Series'!$A$5:$A$24,0)),Config!$G$5))) | F20: =IF($B20="","",Config!$F$5) | H20: =IF($B20="","",SUMIFS('Daily Writing Log'!$H$5:$H$34,'Daily Writing Log'!$B$5:$B$34,$B20)) | I20: =IF($B20="","",IF($G20>0,MIN(1,MAX(0,$Q20/$G20)),0)) | J20: =IF($B20="","",REPT("#",IF($I20>0,MAX(1,ROUNDUP(MIN(1,MAX(0,$I20))*20,0)),0))&REPT("-",20-IF($I20>0,MAX(1,ROUNDUP(MIN(1,MAX(0,$I20))*20,0)),0))) | M20: =IF($B20="","",IF($L20="","",MAX(0,$L20-Config!$A$2))) | N20: =IF($B20="","",IF(OR($G20<=0,$Q20>=$G20),0,IF(OR($L20="",NOT(ISNUMBER($L20))),0,ROUNDUP(MAX(0,$G20-$Q20)/MAX(1,$L20-MAX(Config!$A$2,N($K20))),0)))) | O20: =IF($B20="","",ROUND(SUMIFS('Daily Writing Log'!$F$5:$F$34,'Daily Writing Log'!$B$5:$B$34,$B20,'Daily Writing Log'!$A$5:$A$34,">="&(Config!$A$2-29),'Daily Writing Log'!$A$5:$A$34,"<="&Config!$A$2)/30,0)) | P20: =IF($B20="","",IF($G20<=0,"Add target",IF($Q20>=$G20,"Completed",IF($O20>0,Config!$A$2+ROUNDUP(MAX(0,$G20-$Q20)/$O20,0),"No recent pace")))) | Q20: =IF($B20="","",SUMIFS('Daily Writing Log'!$F$5:$F$34,'Daily Writing Log'!$B$5:$B$34,$B20)) | R20: =IF($B20="","",IF($F20="Published","🎉 Published",IF($G20<=0,"⚪ Set target",IF($Q20>=$G20,"✅ Draft Target Met",IF(AND(ISNUMBER($K20),$K20>Config!$A$2),"⚪ Not Started",IF($F20="Concept","🔵 In Concept",IF(ISBLANK($L20),"In Progress",IF(Config!$A$2>$L20,"🔴 Overdue",IF($O20>=$N20,"🟢 On Track",IF($O20>=$N20*0.6,"🟡 Needs Focus","🔴 Behind Schedule"))))))))))
